Namespace(arch='resnet50', batch_size=16, bottleneck_dim=256, byte_size=512, data='Both', epochs=3, iters_per_epoch=1, label=3, log='Test/', loss_function='SCF', lr=0.003, lr_decay=0.75, lr_gamma=0.0003, momentum=0.9, no_pool=False, non_linear=False, per_class_eval=True, phase='train', print_freq=100, random_frequencies=5, scale_parameter=1, scenario='T2S', scratch=False, seed=None, test_statistic='unnorm', trade_off=0.0, wd=0.0005, workers=2)
Concate data
num_classes: 3
=> using model 'resnet50'
Traceback (most recent call last):
  File "custom_dan.py", line 789, in <module>
    main(args)
  File "custom_dan.py", line 531, in main
    lr_scheduler, epoch, args)
  File "custom_dan.py", line 645, in train
    x_s, labels_s = next(train_source_iter)[:2]
  File "/home/bkcs/miniconda3/lib/python3.7/site-packages/tllib/utils/data.py", line 50, in __next__
    data = next(self.iter)
  File "/home/bkcs/miniconda3/lib/python3.7/site-packages/torch/utils/data/dataloader.py", line 628, in __next__
    data = self._next_data()
  File "/home/bkcs/miniconda3/lib/python3.7/site-packages/torch/utils/data/dataloader.py", line 1333, in _next_data
    return self._process_data(data)
  File "/home/bkcs/miniconda3/lib/python3.7/site-packages/torch/utils/data/dataloader.py", line 1359, in _process_data
    data.reraise()
  File "/home/bkcs/miniconda3/lib/python3.7/site-packages/torch/_utils.py", line 543, in reraise
    raise exception
IndexError: Caught IndexError in DataLoader worker process 0.
Original Traceback (most recent call last):
  File "/home/bkcs/miniconda3/lib/python3.7/site-packages/torch/utils/data/_utils/worker.py", line 302, in _worker_loop
    data = fetcher.fetch(index)
  File "/home/bkcs/miniconda3/lib/python3.7/site-packages/torch/utils/data/_utils/fetch.py", line 58, in fetch
    data = [self.dataset[idx] for idx in possibly_batched_index]
  File "/home/bkcs/miniconda3/lib/python3.7/site-packages/torch/utils/data/_utils/fetch.py", line 58, in <listcomp>
    data = [self.dataset[idx] for idx in possibly_batched_index]
  File "custom_dan.py", line 277, in __getitem__
    return self.data[idx], self.labels[idx]
IndexError: index 9414 is out of bounds for axis 0 with size 6170

