Namespace(arch='resnet50', batch_size=16, bottleneck_dim=256, byte_size=256, data='Both', epochs=3, iters_per_epoch=1, label=3, log='Test/', loss_function='SCF', lr=0.003, lr_decay=0.75, lr_gamma=0.0003, momentum=0.9, no_pool=False, non_linear=False, per_class_eval=True, phase='train', print_freq=100, random_frequencies=5, scale_parameter=1, scenario='T2S', scratch=False, seed=None, test_statistic='unnorm', trade_off=0.0, wd=0.0005, workers=2)
Concate data
Traceback (most recent call last):
  File "/home/bkcs/miniconda3/lib/python3.7/site-packages/pandas/core/indexes/base.py", line 3361, in get_loc
    return self._engine.get_loc(casted_key)
  File "pandas/_libs/index.pyx", line 76, in pandas._libs.index.IndexEngine.get_loc
  File "pandas/_libs/index.pyx", line 108, in pandas._libs.index.IndexEngine.get_loc
  File "pandas/_libs/hashtable_class_helper.pxi", line 5198, in pandas._libs.hashtable.PyObjectHashTable.get_item
  File "pandas/_libs/hashtable_class_helper.pxi", line 5206, in pandas._libs.hashtable.PyObjectHashTable.get_item
KeyError: 0

The above exception was the direct cause of the following exception:

Traceback (most recent call last):
  File "custom_dan.py", line 794, in <module>
    main(args)
  File "custom_dan.py", line 389, in main
    print(train_source[0].shape)
  File "/home/bkcs/miniconda3/lib/python3.7/site-packages/pandas/core/frame.py", line 3458, in __getitem__
    indexer = self.columns.get_loc(key)
  File "/home/bkcs/miniconda3/lib/python3.7/site-packages/pandas/core/indexes/base.py", line 3363, in get_loc
    raise KeyError(key) from err
KeyError: 0
